<mujoco model="gen3">
  <compiler angle="radian" meshdir="assets/"/>

  <option impratio="10" integrator="implicitfast" cone="elliptic"/>

  <visual>
    <global offwidth="1280" offheight="800"/>
    <quality shadowsize="2048"/>
    <headlight ambient="0.3 0.3 0.32" diffuse="0.35 0.35 0.35" specular="0.2 0.2 0.2"/>
  </visual>

  <default>
    <site size="0.001 0.005 0.005" group="4" rgba="0.5 0.5 0.5 0.3"/>
    <default class="visual">
      <geom type="mesh" contype="0" conaffinity="0" group="2" rgba="0.75294 0.75294 0.75294 1"/>
    </default>
    <default class="collision">
      <geom type="mesh" group="3"/>
    </default>
    <default class="large_actuator">
      <general forcerange="-105 105" biastype="affine" gainprm="2000" biasprm="0 -2000 -100"/>
    </default>
    <default class="small_actuator">
      <general forcerange="-52 52" biastype="affine" gainprm="500" biasprm="0 -500 -50"/>
    </default>
    <default class="g_main">
      <site size="0.005 0.005 0.005" group="0" rgba="0.5 0.5 0.5 1"/>
      <default class="g_2f85">
        <mesh scale="0.001 0.001 0.001"/>
        <general biastype="affine"/>
        <default class="g_driver">
          <joint solreflimit="0.005" solimplimit="0.95 0.99" range="0 0.8" armature="0.005" damping="0.1"/>
        </default>
        <default class="g_follower">
          <joint solreflimit="0.005" solimplimit="0.95 0.99" range="-0.872664 0.872664" armature="0.001"/>
        </default>
        <default class="g_spring_link">
          <joint springref="2.62" stiffness="0.05" range="-0.296706 0.8" armature="0.001" damping="0.00125"/>
        </default>
        <default class="g_coupler">
          <joint solreflimit="0.005" solimplimit="0.95 0.99" range="-1.57 0" armature="0.001"/>
        </default>
        <default class="g_visual">
          <geom type="mesh" contype="0" conaffinity="0" group="2"/>
        </default>
        <default class="g_collision">
          <geom type="mesh" group="3"/>
          <default class="g_pad_box1">
            <geom size="0.011 0.004 0.009375" type="box" priority="1" friction="0.7" solref="0.004" solimp="0.95 0.99" rgba="0.55 0.55 0.55 1"/>
          </default>
          <default class="g_pad_box2">
            <geom size="0.011 0.004 0.009375" type="box" priority="1" friction="0.6" solref="0.004" solimp="0.95 0.99" rgba="0.45 0.45 0.45 1"/>
          </default>
        </default>
      </default>
    </default>
  </default>

  <asset>
    <texture type="skybox" colorspace="auto" name="sky" builtin="gradient" rgb1="0.62 0.7 0.8" rgb2="0.18 0.22 0.3" width="512" height="3072"/>
    <texture type="2d" colorspace="auto" name="tex_floor" builtin="checker" mark="edge" rgb1="0.31 0.32 0.34" rgb2="0.38 0.39 0.42" markrgb="0.24 0.25 0.27" width="300" height="300"/>
    <material name="g_metal" rgba="0.58 0.58 0.58 1"/>
    <material name="g_silicone" rgba="0.1882 0.1882 0.1882 1"/>
    <material name="g_gray" rgba="0.4627 0.4627 0.4627 1"/>
    <material name="g_black" rgba="0.149 0.149 0.149 1"/>
    <material name="mat_floor" texture="tex_floor" texrepeat="10 10" specular="0.2" shininess="0.2" reflectance="0.12"/>
    <material name="mat_wood" specular="0.25" shininess="0.35" rgba="0.55 0.39 0.25 1"/>
    <material name="mat_wood_dark" specular="0.2" shininess="0.3" rgba="0.33 0.22 0.14 1"/>
    <material name="mat_wood_mid" specular="0.2" shininess="0.3" rgba="0.44 0.3 0.19 1"/>
    <material name="mat_wall" specular="0.05" shininess="0.05" rgba="0.78 0.77 0.73 1"/>
    <material name="mat_metal" specular="0.9" shininess="0.8" reflectance="0.25" rgba="0.75 0.77 0.8 1"/>
    <material name="mat_pedestal" specular="0.6" shininess="0.6" rgba="0.22 0.23 0.25 1"/>
    <material name="mat_counter" specular="0.55" shininess="0.6" reflectance="0.08" rgba="0.35 0.36 0.39 1"/>
    <material name="mat_white" rgba="0.91 0.92 0.94 1"/>
    <material name="mat_dark" specular="0.4" rgba="0.17 0.17 0.19 1"/>
    <mesh name="base_link" file="D:\mujoco_menagerie\kinova_gen3\assets\base_link.stl"/>
    <mesh name="shoulder_link" file="D:\mujoco_menagerie\kinova_gen3\assets\shoulder_link.stl"/>
    <mesh name="half_arm_1_link" file="D:\mujoco_menagerie\kinova_gen3\assets\half_arm_1_link.stl"/>
    <mesh name="half_arm_2_link" file="D:\mujoco_menagerie\kinova_gen3\assets\half_arm_2_link.stl"/>
    <mesh name="forearm_link" file="D:\mujoco_menagerie\kinova_gen3\assets\forearm_link.stl"/>
    <mesh name="spherical_wrist_1_link" file="D:\mujoco_menagerie\kinova_gen3\assets\spherical_wrist_1_link.stl"/>
    <mesh name="spherical_wrist_2_link" file="D:\mujoco_menagerie\kinova_gen3\assets\spherical_wrist_2_link.stl"/>
    <mesh name="bracelet_with_vision_link" file="D:\mujoco_menagerie\kinova_gen3\assets\bracelet_with_vision_link.stl"/>
    <mesh name="g_base_mount" class="g_2f85" file="D:\mujoco_menagerie\robotiq_2f85\assets\base_mount.stl"/>
    <mesh name="g_base" class="g_2f85" file="D:\mujoco_menagerie\robotiq_2f85\assets\base.stl"/>
    <mesh name="g_driver" class="g_2f85" file="D:\mujoco_menagerie\robotiq_2f85\assets\driver.stl"/>
    <mesh name="g_coupler" class="g_2f85" file="D:\mujoco_menagerie\robotiq_2f85\assets\coupler.stl"/>
    <mesh name="g_follower" class="g_2f85" file="D:\mujoco_menagerie\robotiq_2f85\assets\follower.stl"/>
    <mesh name="g_pad" class="g_2f85" file="D:\mujoco_menagerie\robotiq_2f85\assets\pad.stl"/>
    <mesh name="g_silicone_pad" class="g_2f85" file="D:\mujoco_menagerie\robotiq_2f85\assets\silicone_pad.stl"/>
    <mesh name="g_spring_link" class="g_2f85" file="D:\mujoco_menagerie\robotiq_2f85\assets\spring_link.stl"/>
  </asset>

  <worldbody>
    <geom name="floor" size="4 4 0.1" pos="0 0 -0.75" type="plane" material="mat_floor"/>
    <geom name="obs_table_top" size="0.65 0.7 0.03" pos="0.15 0 -0.1" type="box" material="mat_counter"/>
    <geom name="obs_table_base" size="0.6 0.65 0.28" pos="0.15 0 -0.41" type="box" material="mat_wood_mid"/>
    <geom name="obs_table_kick" size="0.55 0.6 0.03" pos="0.15 0 -0.72" type="box" material="mat_dark"/>
    <geom name="obs_back_wall_main" size="0.02 1.2 0.5" pos="1.07 0 0.4" type="box" material="mat_wall"/>
    <geom name="obs_back_wall_lower" size="0.02 1.2 0.325" pos="1.07 0 -0.425" type="box" material="mat_wall"/>
    <geom name="obs_back_wall_baseboard" size="0.012 1.2 0.045" pos="1.038 0 -0.705" type="box" material="mat_wood_dark"/>
    <geom name="obs_wall_window" size="0.004 0.26 0.22" pos="1.044 0.42 0.62" type="box" contype="0" conaffinity="0" rgba="0.72 0.86 0.97 1"/>
    <geom name="obs_wall_winframe0" size="0.006 0.27 0.015" pos="1.04 0.42 0.84" type="box" contype="0" conaffinity="0" rgba="0.95 0.95 0.96 1"/>
    <geom name="obs_wall_winframe1" size="0.006 0.27 0.015" pos="1.04 0.42 0.4" type="box" contype="0" conaffinity="0" rgba="0.95 0.95 0.96 1"/>
    <geom name="obs_wall_winframe2" size="0.006 0.015 0.235" pos="1.04 0.68 0.62" type="box" contype="0" conaffinity="0" rgba="0.95 0.95 0.96 1"/>
    <geom name="obs_wall_winframe3" size="0.006 0.015 0.235" pos="1.04 0.16 0.62" type="box" contype="0" conaffinity="0" rgba="0.95 0.95 0.96 1"/>
    <geom name="obs_wall_winframe4" size="0.006 0.012 0.22" pos="1.04 0.42 0.62" type="box" contype="0" conaffinity="0" rgba="0.95 0.95 0.96 1"/>
    <geom name="obs_wall_counter_top" size="0.13 1 0.045" pos="0.92 0 -0.085" type="box" material="mat_counter"/>
    <geom name="obs_wall_counter_base" size="0.11 0.98 0.28" pos="0.94 0 -0.41" type="box" material="mat_wood_mid"/>
    <geom name="obs_wall_counter_kick" size="0.08 0.94 0.03" pos="0.97 0 -0.72" type="box" material="mat_dark"/>
    <geom name="obs_cabinet_main" size="0.15 0.15 0.275" pos="0.45 -0.52 0.28" type="box" material="mat_wood_dark"/>
    <geom name="obs_cabinet_top_lip" size="0.15 0.15 0.006" pos="0.45 -0.52 0.549" type="box" material="mat_wood_mid"/>
    <geom name="obs_cabinet_plinth" size="0.13 0.13 0.0375" pos="0.45 -0.52 -0.0325" type="box" material="mat_wood_dark"/>
    <geom name="obs_shelf_slab" size="0.17 0.15 0.015" pos="0.55 0.42 0.5" type="box" material="mat_wood"/>
    <geom name="obs_upper_cabinet_main" size="0.15 0.35 0.225" pos="0.95 -0.35 0.95" type="box" material="mat_wood_mid"/>
    <geom name="obs_upper_cabinet_door_l" size="0.006 0.161 0.2025" pos="0.794 -0.525 0.95" type="box" material="mat_wood_dark"/>
    <geom name="obs_upper_cabinet_knob_l" size="0.008 0.008 0.008" pos="0.78 -0.4 0.7925" type="box" material="mat_metal"/>
    <geom name="obs_upper_cabinet_door_r" size="0.006 0.161 0.2025" pos="0.794 -0.175 0.95" type="box" material="mat_wood_dark"/>
    <geom name="obs_upper_cabinet_knob_r" size="0.008 0.008 0.008" pos="0.78 -0.3 0.7925" type="box" material="mat_metal"/>
    <geom name="obs_microwave_body" size="0.15 0.225 0.125" pos="0.9 0.42 0.085" type="box" material="mat_dark"/>
    <geom name="obs_microwave_window" size="0.004 0.12375 0.0775" pos="0.746 0.45375 0.085" type="box" material="mat_pedestal"/>
    <geom name="obs_microwave_handle" size="0.008 0.008 0.0875" pos="0.738 0.225 0.085" type="box" material="mat_metal"/>
    <geom name="obs_fridge_body" size="0.325 0.325 0.7" pos="0.55 -1.05 -0.05" type="box" material="mat_white"/>
    <geom name="obs_fridge_door_split" size="0.327 0.325 0.004" pos="0.55 -1.05 0.125" type="box" material="mat_pedestal"/>
    <geom name="obs_fridge_handle_t" size="0.012 0.012 0.1" pos="0.21 -1.305 0.174" type="box" material="mat_metal"/>
    <geom name="obs_fridge_handle_b" size="0.012 0.012 0.1" pos="0.21 -1.305 0.05" type="box" material="mat_metal"/>
    <geom name="obs_stool_seat" size="0.175 0.175 0.02" pos="-0.8 0.55 -0.17" type="box" material="mat_wood"/>
    <geom name="obs_stool_leg_0" size="0.018 0.018 0.28" pos="-0.655 0.695 -0.47" type="box" material="mat_wood_dark"/>
    <geom name="obs_stool_leg_1" size="0.018 0.018 0.28" pos="-0.655 0.405 -0.47" type="box" material="mat_wood_dark"/>
    <geom name="obs_stool_leg_2" size="0.018 0.018 0.28" pos="-0.945 0.695 -0.47" type="box" material="mat_wood_dark"/>
    <geom name="obs_stool_leg_3" size="0.018 0.018 0.28" pos="-0.945 0.405 -0.47" type="box" material="mat_wood_dark"/>
    <geom name="obs_trash_body" size="0.125 0.25" pos="-0.7 -0.6 -0.5" type="cylinder" material="mat_dark"/>
    <geom name="obs_trash_lip" size="0.133 0.012" pos="-0.7 -0.6 -0.262" type="cylinder" material="mat_pedestal"/>
    <geom name="obs_pedestal" size="0.07 0.035" pos="0 0 -0.035" type="cylinder" material="mat_pedestal"/>
    <geom name="obj_placemat_geom" size="0.15 0.11 0.003" pos="0.08 -0.45 -0.067" type="box" density="400" rgba="0.35 0.28 0.45 1"/>
    <geom name="obj_kettle_body" size="0.09 0.064" pos="0.9 -0.3 0.03" type="cylinder" material="mat_dark"/>
    <geom name="obj_kettle_lid" size="0.072 0.072 0.024" pos="0.9 -0.3 0.1" type="ellipsoid" contype="0" conaffinity="0" material="mat_metal"/>
    <geom name="obj_kettle_spout" size="0.014 0.05" pos="0.79 -0.3 0.07" quat="0.422618 0 0.906308 0" type="capsule" contype="0" conaffinity="0" material="mat_dark"/>
    <geom name="obj_kettle_handle" size="0.01 0.05" pos="0.936 -0.3 0.128" quat="0.793353 0 0.608761 0" type="capsule" contype="0" conaffinity="0" material="mat_dark"/>
    <geom name="obj_cutting_board_geom" size="0.13 0.09 0.008" pos="0.08 0.48 -0.062" type="box" density="400" rgba="0.62 0.46 0.28 1"/>
    <geom name="obj_door" size="0.0075 0.12 0.22" pos="0.295 -0.52 0.3" type="box" material="mat_wood_mid"/>
    <geom name="obj_door_panel" size="0.004 0.0864 0.1716" pos="0.2835 -0.52 0.3" type="box" contype="0" conaffinity="0" material="mat_wood_dark"/>
    <geom name="obj_handle_bar" size="0.008 0.008 0.06" pos="0.278 -0.41 0.34" type="box" material="mat_metal"/>
    <geom name="obj_handle_nub_t" size="0.01 0.006 0.006" pos="0.284 -0.41 0.385" type="box" contype="0" conaffinity="0" material="mat_metal"/>
    <geom name="obj_handle_nub_b" size="0.01 0.006 0.006" pos="0.284 -0.41 0.295" type="box" contype="0" conaffinity="0" material="mat_metal"/>
    <geom name="obj_shelf_post_front" size="0.015 0.015 0.2775" pos="0.68 0.3 0.2075" type="box" material="mat_wood_mid"/>
    <geom name="obj_shelf_post_back" size="0.015 0.015 0.2775" pos="0.68 0.54 0.2075" type="box" material="mat_wood_mid"/>
    <camera name="viz_cam" pos="-1.3 -1 0.9" quat="0.726965 0.495966 -0.267648 -0.392307"/>
    <camera name="scene_cam" pos="-0.75 0 1.45" quat="0.681514 0.188517 -0.188517 -0.681514" resolution="640 480" fovy="58"/>
    <light name="key" pos="-1.5 -1.3 1.7" dir="0.659571 0.439714 -0.609604" diffuse="0.75 0.72 0.66"/>
    <light name="fill" pos="-1.2 1.5 1.2" dir="0.501406 -0.601687 -0.621743" castshadow="false" diffuse="0.28 0.3 0.36"/>
    <light name="top" pos="0.3 0 2.4" dir="0 0 -1" castshadow="false" diffuse="0.3 0.3 0.3"/>
    <body name="base_link">
      <inertial pos="-0.000648 -0.000166 0.084487" quat="0.999294 0.00139618 -0.0118387 0.035636" mass="1.697" diaginertia="0.00462407 0.00449437 0.00207755"/>
      <geom class="visual" mesh="base_link"/>
      <geom class="collision" mesh="base_link"/>
      <body name="shoulder_link" pos="0 0 0.15643" quat="0 1 0 0">
        <inertial pos="-2.3e-05 -0.010364 -0.07336" quat="0.707051 0.0451246 -0.0453544 0.704263" mass="1.3773" diaginertia="0.00488868 0.00457 0.00135132"/>
        <joint name="joint_1" pos="0 0 0" axis="0 0 1"/>
        <geom class="visual" mesh="shoulder_link"/>
        <geom class="collision" mesh="shoulder_link"/>
        <body name="half_arm_1_link" pos="0 0.005375 -0.12838" quat="0.707107 0.707107 0 0">
          <inertial pos="-4.4e-05 -0.09958 -0.013278" quat="0.482348 0.516286 -0.516862 0.483366" mass="1.1636" diaginertia="0.0113017 0.011088 0.00102532"/>
          <joint name="joint_2" pos="0 0 0" axis="0 0 1" range="-2.24 2.24"/>
          <geom class="visual" mesh="half_arm_1_link"/>
          <geom class="collision" mesh="half_arm_1_link"/>
          <body name="half_arm_2_link" pos="0 -0.21038 -0.006375" quat="0.707107 -0.707107 0 0">
            <inertial pos="-4.4e-05 -0.006641 -0.117892" quat="0.706144 0.0213722 -0.0209128 0.707437" mass="1.1636" diaginertia="0.0111633 0.010932 0.00100671"/>
            <joint name="joint_3" pos="0 0 0" axis="0 0 1"/>
            <geom class="visual" mesh="half_arm_2_link"/>
            <geom class="collision" mesh="half_arm_2_link"/>
            <body name="forearm_link" pos="0 0.006375 -0.21038" quat="0.707107 0.707107 0 0">
              <inertial pos="-1.8e-05 -0.075478 -0.015006" quat="0.483678 0.515961 -0.515859 0.483455" mass="0.9302" diaginertia="0.00834839 0.008147 0.000598606"/>
              <joint name="joint_4" pos="0 0 0" axis="0 0 1" range="-2.57 2.57"/>
              <geom class="visual" mesh="forearm_link"/>
              <geom class="collision" mesh="forearm_link"/>
              <body name="spherical_wrist_1_link" pos="0 -0.20843 -0.006375" quat="0.707107 -0.707107 0 0">
                <inertial pos="1e-06 -0.009432 -0.063883" quat="0.703558 0.0707492 -0.0707492 0.703558" mass="0.6781" diaginertia="0.00165901 0.001596 0.000346988"/>
                <joint name="joint_5" pos="0 0 0" axis="0 0 1"/>
                <geom class="visual" mesh="spherical_wrist_1_link"/>
                <geom class="collision" mesh="spherical_wrist_1_link"/>
                <body name="spherical_wrist_2_link" pos="0 0.00017505 -0.10593" quat="0.707107 0.707107 0 0">
                  <inertial pos="1e-06 -0.045483 -0.00965" quat="0.44426 0.550121 -0.550121 0.44426" mass="0.6781" diaginertia="0.00170087 0.001641 0.00035013"/>
                  <joint name="joint_6" pos="0 0 0" axis="0 0 1" range="-2.09 2.09"/>
                  <geom class="visual" mesh="spherical_wrist_2_link"/>
                  <geom class="collision" mesh="spherical_wrist_2_link"/>
                  <body name="bracelet_link" pos="0 -0.10593 -0.00017505" quat="0.707107 -0.707107 0 0">
                    <inertial pos="0.000281 0.011402 -0.029798" quat="0.394358 0.596779 -0.577293 0.393789" mass="0.5" diaginertia="0.000657336 0.000587019 0.000320645"/>
                    <joint name="joint_7" pos="0 0 0" axis="0 0 1"/>
                    <geom class="visual" mesh="bracelet_with_vision_link"/>
                    <geom class="collision" mesh="bracelet_with_vision_link"/>
                    <site name="pinch_site" pos="0 0 -0.061525" quat="0 1 0 0"/>
                    <camera name="wrist" pos="0 -0.05639 -0.058475" quat="0 0 0 1" fovy="41.8379"/>
                    <camera name="d405" pos="0 -0.058 -0.078" quat="0 0 0 1" resolution="640 480" fovy="58"/>
                    <body name="g_base" childclass="g_2f85" pos="0 0 -0.0652904" quat="0 -0.707107 0.707107 0">
                      <inertial pos="0 -2.70394e-05 0.0354675" quat="0.999999 -0.00152849 0 0" mass="0.777441" diaginertia="0.000260285 0.000225381 0.000152708"/>
                      <geom class="g_visual" material="g_black" mesh="g_base"/>
                      <geom class="g_collision" mesh="g_base"/>
                      <site name="g_pinch" pos="0 0 0.145" group="5" rgba="0.9 0.9 0.9 1"/>
                      <body name="g_right_driver" pos="0 0.0306011 0.054904">
                        <inertial pos="2.96931e-12 0.0177547 0.00107314" quat="0.681301 0.732003 0 0" mass="0.00899563" diaginertia="1.72352e-06 1.60906e-06 3.22006e-07"/>
                        <joint name="g_right_driver_joint" class="g_driver" pos="0 0 0" axis="1 0 0"/>
                        <geom class="g_visual" material="g_gray" mesh="g_driver"/>
                        <geom class="g_collision" mesh="g_driver"/>
                        <body name="g_right_coupler" pos="0 0.0315 -0.0041">
                          <inertial pos="0 0.00301209 0.0232175" quat="0.705636 -0.0455904 0.0455904 0.705636" mass="0.0140974" diaginertia="4.16206e-06 3.52216e-06 8.88131e-07"/>
                          <joint name="g_right_coupler_joint" class="g_coupler" pos="0 0 0" axis="1 0 0"/>
                          <geom class="g_visual" material="g_black" mesh="g_coupler"/>
                          <geom class="g_collision" mesh="g_coupler"/>
                        </body>
                      </body>
                      <body name="g_right_spring_link" pos="0 0.0132 0.0609">
                        <inertial pos="-8.65005e-09 0.0181624 0.0212658" quat="0.663403 -0.244737 0.244737 0.663403" mass="0.0221642" diaginertia="8.96853e-06 6.71733e-06 2.63931e-06"/>
                        <joint name="g_right_spring_link_joint" class="g_spring_link" pos="0 0 0" axis="1 0 0" springref="2.62"/>
                        <geom class="g_visual" material="g_black" mesh="g_spring_link"/>
                        <geom class="g_collision" mesh="g_spring_link"/>
                        <body name="g_right_follower" pos="0 0.055 0.0375">
                          <inertial pos="0 -0.011046 0.0124786" quat="0.986437 0.164143 0 0" mass="0.0125222" diaginertia="2.67415e-06 2.4559e-06 6.02031e-07"/>
                          <joint name="g_right_follower_joint" class="g_follower" pos="0 -0.018 0.0065" axis="1 0 0"/>
                          <geom class="g_visual" material="g_black" mesh="g_follower"/>
                          <geom class="g_collision" mesh="g_follower"/>
                          <body name="g_right_pad" pos="0 -0.0189 0.01352">
                            <inertial pos="0 -0.0025 0.0185" quat="0.707107 0 0 0.707107" mass="0.0035" diaginertia="4.73958e-07 3.64583e-07 1.23958e-07"/>
                            <geom name="g_right_pad1" class="g_pad_box1" pos="0 -0.0026 0.028125" mass="0"/>
                            <geom name="g_right_pad2" class="g_pad_box2" pos="0 -0.0026 0.009375" mass="0"/>
                            <geom class="g_visual" mesh="g_pad"/>
                            <body name="g_right_silicone_pad">
                              <geom class="g_visual" material="g_black" mesh="g_silicone_pad"/>
                            </body>
                          </body>
                        </body>
                      </body>
                      <body name="g_left_driver" pos="0 -0.0306011 0.054904" quat="0 0 0 1">
                        <inertial pos="0 0.0177547 0.00107314" quat="0.681301 0.732003 0 0" mass="0.00899563" diaginertia="1.72352e-06 1.60906e-06 3.22006e-07"/>
                        <joint name="robotiq_85_left_knuckle_joint" class="g_driver" pos="0 0 0" axis="1 0 0"/>
                        <geom class="g_visual" material="g_gray" mesh="g_driver"/>
                        <geom class="g_collision" mesh="g_driver"/>
                        <body name="g_left_coupler" pos="0 0.0315 -0.0041">
                          <inertial pos="0 0.00301209 0.0232175" quat="0.705636 -0.0455904 0.0455904 0.705636" mass="0.0140974" diaginertia="4.16206e-06 3.52216e-06 8.88131e-07"/>
                          <joint name="g_left_coupler_joint" class="g_coupler" pos="0 0 0" axis="1 0 0"/>
                          <geom class="g_visual" material="g_black" mesh="g_coupler"/>
                          <geom class="g_collision" mesh="g_coupler"/>
                        </body>
                      </body>
                      <body name="g_left_spring_link" pos="0 -0.0132 0.0609" quat="0 0 0 1">
                        <inertial pos="-8.65005e-09 0.0181624 0.0212658" quat="0.663403 -0.244737 0.244737 0.663403" mass="0.0221642" diaginertia="8.96853e-06 6.71733e-06 2.63931e-06"/>
                        <joint name="g_left_spring_link_joint" class="g_spring_link" pos="0 0 0" axis="1 0 0" springref="2.62"/>
                        <geom class="g_visual" material="g_black" mesh="g_spring_link"/>
                        <geom class="g_collision" mesh="g_spring_link"/>
                        <body name="g_left_follower" pos="0 0.055 0.0375">
                          <inertial pos="0 -0.011046 0.0124786" quat="0.986437 0.164143 0 0" mass="0.0125222" diaginertia="2.67415e-06 2.4559e-06 6.02031e-07"/>
                          <joint name="g_left_follower_joint" class="g_follower" pos="0 -0.018 0.0065" axis="1 0 0"/>
                          <geom class="g_visual" material="g_black" mesh="g_follower"/>
                          <geom class="g_collision" mesh="g_follower"/>
                          <body name="g_left_pad" pos="0 -0.0189 0.01352">
                            <inertial pos="0 -0.0025 0.0185" quat="0.707107 0 0 0.707107" mass="0.0035" diaginertia="4.73958e-07 3.64583e-07 1.23958e-07"/>
                            <geom name="g_left_pad1" class="g_pad_box1" pos="0 -0.0026 0.028125" mass="0"/>
                            <geom name="g_left_pad2" class="g_pad_box2" pos="0 -0.0026 0.009375" mass="0"/>
                            <geom class="g_visual" mesh="g_pad"/>
                            <body name="g_left_silicone_pad">
                              <geom class="g_visual" material="g_black" mesh="g_silicone_pad"/>
                            </body>
                          </body>
                        </body>
                      </body>
                    </body>
                  </body>
                </body>
              </body>
            </body>
          </body>
        </body>
      </body>
    </body>
    <body name="obj_bottle" pos="0.45 0.12 0.04">
      <joint type="free"/>
      <geom name="obj_bottle_body" size="0.033 0.0682" pos="0 0 -0.0418" type="cylinder" condim="6" friction="0.9 0.02 0.002" density="300" rgba="0.25 0.55 0.85 1"/>
      <geom name="obj_bottle_shoulder" size="0.03135 0.03135 0.0154" pos="0 0 0.0264" type="ellipsoid" condim="6" friction="0.9 0.02 0.002" density="300" rgba="0.25 0.55 0.85 1"/>
      <geom name="obj_bottle_neck" size="0.01485 0.0198" pos="0 0 0.0594" type="cylinder" condim="6" friction="0.9 0.02 0.002" density="300" rgba="0.25 0.55 0.85 1"/>
      <geom name="obj_bottle_cap" size="0.01815 0.0154" pos="0 0 0.0946" type="cylinder" condim="6" friction="0.9 0.02 0.002" density="300" rgba="0.92 0.94 0.96 1"/>
    </body>
    <body name="obj_mug" pos="-0.45 -0.14 -0.025" quat="-0.147809 0 0 0.989016">
      <joint type="free"/>
      <geom name="obj_mug_body" size="0.032 0.045" type="cylinder" condim="6" friction="0.9 0.02 0.002" density="400" rgba="0.15 0.55 0.35 1"/>
      <geom name="obj_mug_inner" size="0.0256 0.002" pos="0 0 0.042" type="cylinder" contype="0" conaffinity="0" density="100" rgba="0.15 0.1 0.08 1"/>
      <geom name="obj_mug_handle_v" size="0.005 0.02" pos="0.055 0 0" type="capsule" contype="0" conaffinity="0" density="100" rgba="0.15 0.55 0.35 1"/>
      <geom name="obj_mug_handle_t" size="0.0045 0.011" pos="0.043 0 0.021" quat="0.707107 0 0.707107 0" type="capsule" contype="0" conaffinity="0" density="100" rgba="0.15 0.55 0.35 1"/>
      <geom name="obj_mug_handle_b" size="0.0045 0.011" pos="0.043 0 -0.021" quat="0.707107 0 0.707107 0" type="capsule" contype="0" conaffinity="0" density="100" rgba="0.15 0.55 0.35 1"/>
    </body>
    <body name="obj_plate" pos="0.08 -0.45 -0.06">
      <joint type="free"/>
      <geom name="obj_plate_base" size="0.0495 0.005" pos="0 0 -0.005" type="cylinder" condim="6" friction="0.9 0.02 0.002" density="800" rgba="0.2 0.62 0.6 1"/>
      <geom name="obj_plate_top" size="0.09 0.005" pos="0 0 0.005" type="cylinder" condim="6" friction="0.9 0.02 0.002" density="800" rgba="0.2 0.62 0.6 1"/>
    </body>
    <body name="obj_snack_box" pos="0.52 0.4 0.61">
      <joint type="free"/>
      <geom name="obj_snack_box" size="0.0275 0.07 0.095" type="box" condim="6" friction="0.9 0.02 0.002" density="150" rgba="0.48 0.22 0.58 1"/>
      <geom name="obj_snack_label" size="0.0015 0.056 0.0627" pos="0.029 0 0" type="box" contype="0" conaffinity="0" density="50" rgba="0.95 0.91 0.8 1"/>
    </body>
    <body name="obj_bowl" pos="-0.3 0.3 -0.045">
      <joint type="free"/>
      <geom name="obj_bowl_base" size="0.04125 0.0125" pos="0 0 -0.0125" type="cylinder" condim="6" friction="0.9 0.02 0.002" density="500" rgba="0.85 0.25 0.5 1"/>
      <geom name="obj_bowl_body" size="0.075 0.0125" pos="0 0 0.0125" type="cylinder" condim="6" friction="0.9 0.02 0.002" density="500" rgba="0.85 0.25 0.5 1"/>
      <geom name="obj_bowl_inner" size="0.06 0.003" pos="0 0 0.021" type="cylinder" contype="0" conaffinity="0" density="50" rgba="0.55 0.42 0.3 1"/>
    </body>
    <body name="obj_pill_bottle" pos="0.52 0.06 -0.025">
      <joint type="free"/>
      <geom name="obj_pills_body" size="0.022 0.0324" pos="0 0 -0.0126" type="cylinder" condim="6" friction="0.9 0.02 0.002" density="250" rgba="0.93 0.5 0.12 1"/>
      <geom name="obj_pills_cap" size="0.0231 0.0126" pos="0 0 0.0324" type="cylinder" condim="6" friction="0.9 0.02 0.002" density="250" rgba="0.95 0.95 0.97 1"/>
    </body>
    <body name="obj_banana" pos="-0.18 0.53 -0.05" quat="0.976296 0 0 -0.21644">
      <joint type="free"/>
      <geom name="obj_banana_a" size="0.017 0.032" pos="-0.055 0 0.014" quat="0.829038 0 0.559193 0" type="capsule" condim="6" friction="0.9 0.02 0.002" density="300" rgba="0.91 0.79 0.18 1"/>
      <geom name="obj_banana_b" size="0.017 0.032" pos="0 0 0.004" quat="0.707107 0 0.707107 0" type="capsule" condim="6" friction="0.9 0.02 0.002" density="300" rgba="0.91 0.79 0.18 1"/>
      <geom name="obj_banana_c" size="0.017 0.032" pos="0.055 0 0.014" quat="0.559193 0 0.829038 0" type="capsule" condim="6" friction="0.9 0.02 0.002" density="300" rgba="0.91 0.79 0.18 1"/>
    </body>
    <body name="obj_apple" pos="-0.46 0.16 -0.035">
      <joint type="free"/>
      <geom name="obj_apple_body" size="0.035" condim="6" friction="0.9 0.02 0.002" density="700" rgba="0.75 0.15 0.12 1"/>
      <geom name="obj_apple_stem" size="0.003 0.01" pos="0 0 0.043" type="capsule" contype="0" conaffinity="0" density="50" rgba="0.35 0.25 0.12 1"/>
    </body>
  </worldbody>

  <contact>
    <exclude body1="base_link" body2="shoulder_link"/>
    <exclude body1="g_base" body2="g_right_driver"/>
    <exclude body1="g_base" body2="g_right_spring_link"/>
    <exclude body1="g_base" body2="g_left_driver"/>
    <exclude body1="g_base" body2="g_left_spring_link"/>
    <exclude body1="g_right_coupler" body2="g_right_follower"/>
    <exclude body1="g_left_coupler" body2="g_left_follower"/>
  </contact>

  <equality>
    <connect body1="g_right_follower" body2="g_right_coupler" anchor="0 0 0" solref="0.005" solimp="0.95 0.99"/>
    <connect body1="g_left_follower" body2="g_left_coupler" anchor="0 0 0" solref="0.005" solimp="0.95 0.99"/>
    <joint joint1="g_right_driver_joint" joint2="robotiq_85_left_knuckle_joint" polycoef="0 1 0 0 0" solref="0.005" solimp="0.95 0.99"/>
  </equality>

  <tendon>
    <fixed name="g_split">
      <joint joint="g_right_driver_joint" coef="0.5"/>
      <joint joint="robotiq_85_left_knuckle_joint" coef="0.5"/>
    </fixed>
  </tendon>

  <actuator>
    <general name="joint_1" class="large_actuator" joint="joint_1"/>
    <general name="joint_2" class="large_actuator" joint="joint_2" ctrlrange="-2.24973 2.24973"/>
    <general name="joint_3" class="large_actuator" joint="joint_3"/>
    <general name="joint_4" class="large_actuator" joint="joint_4" ctrlrange="-2.5796 2.5796"/>
    <general name="joint_5" class="small_actuator" joint="joint_5"/>
    <general name="joint_6" class="small_actuator" joint="joint_6" ctrlrange="-2.09963 2.09963"/>
    <general name="joint_7" class="small_actuator" joint="joint_7"/>
    <general name="robotiq_85_left_knuckle_joint" class="g_2f85" tendon="g_split" ctrlrange="0 0.8" forcerange="-5 5" gainprm="100" biasprm="0 -100 -10"/>
  </actuator>
</mujoco>
